<?xml version="1.0" encoding="UTF-8"?>
<robot xmlns:xacro="http://www.ros.org/wiki/xacro">
  <xacro:macro name="wheel" params="prefix y_reflect">
    <link name="${prefix}_link">
      <visual>
        <origin xyz="0 0 0" rpy="${pi/2} 0 0"/>
        <geometry>
          <cylinder radius="${wheel_radius}" length="${wheel_width}"/>
        </geometry>
        <material name="gray"/>
      </visual>
    </link>

    <joint name="${prefix}_joint" type="continuous">
      <parent link="base_link"/>
      <child link="${prefix}_link"/>
      <origin xyz="0 ${y_reflect * (base_width / 2 + wheel_ygap + wheel_width / 2)} ${-wheel_zoff}" rpy="0 0 0"/>
      <axis xyz="0 1 0"/>
    </joint>
  </xacro:macro>

  <xacro:macro name="caster_wheel" params="prefix y_reflect">
    <link name="${prefix}_link">
      <visual>
        <geometry>
          <sphere radius="${wheel_radius}"/>
        </geometry>
        <material name="gray"/>
      </visual>
    </link>

    <joint name="${prefix}_joint" type="fixed">
      <parent link="base_link"/>
      <child link="${prefix}_link"/>
      <origin xyz="${caster_xoff} ${y_reflect*caster_yoff} ${-wheel_zoff}" rpy="0 0 0"/>
    </joint>
  </xacro:macro>
</robot>